2020-10-04 17:51:11 default[20201004t144116]  [2020-10-04 17:51:11 +0000] [24] [INFO] Worker exiting (pid: 24)
2020-10-04 17:51:11 default[20201004t144116]  [2020-10-04 17:51:11 +0000] [20] [ERROR] Exception in worker process
2020-10-04 17:51:11 default[20201004t144116]  Traceback (most recent call last):    File "/layers/google.python.webserver/gunicorn/gunicorn/arbiter.py", line 583, in spawn_worker      worker.init_process()    File "/layers/google.python.webserver/gunicorn/gunicorn/workers/gthread.py", line 92, in init_process      super().init_process()    File "/layers/google.python.webserver/gunicorn/gunicorn/workers/base.py", line 119, in init_process      self.load_wsgi()    File "/layers/google.python.webserver/gunicorn/gunicorn/workers/base.py", line 144, in load_wsgi      self.wsgi = self.app.wsgi()    File "/layers/google.python.webserver/gunicorn/gunicorn/app/base.py", line 67, in wsgi      self.callable = self.load()    File "/layers/google.python.webserver/gunicorn/gunicorn/app/wsgiapp.py", line 49, in load      return self.load_wsgiapp()    File "/layers/google.python.webserver/gunicorn/gunicorn/app/wsgiapp.py", line 39, in load_wsgiapp      return util.import_app(self.app_uri)    File "/layers/google.python.webserver/gunicorn/gunicorn/util.py", line 358, in import_app      mod = importlib.import_module(module)    File "/opt/python3.8/lib/python3.8/importlib/__init__.py", line 127, in import_module      return _bootstrap._gcd_import(name[level:], package, level)    File "<frozen importlib._bootstrap>", line 1014, in _gcd_import    File "<frozen importlib._bootstrap>", line 991, in _find_and_load    File "<frozen importlib._bootstrap>", line 975, in _find_and_load_unlocked    File "<frozen importlib._bootstrap>", line 671, in _load_unlocked    File "<frozen importlib._bootstrap_external>", line 783, in exec_module    File "<frozen importlib._bootstrap>", line 219, in _call_with_frames_removed    File "/srv/main.py", line 7, in <module>      app.run(debug=True, host="0.0.0.0", port=port)    File "/layers/google.python.pip/pip/flask/app.py", line 990, in run      run_simple(host, port, self, **options)    File "/layers/google.python.pip/pip/werkzeug/serving.py", line 1030, in run_simple      s.bind(server_address)  OSError: [Errno 98] Address already in use
2020-10-04 17:51:11 default[20201004t144116]  [2020-10-04 17:51:11 +0000] [20] [INFO] Worker exiting (pid: 20)
2020-10-04 17:51:11 default[20201004t144116]  [2020-10-04 17:51:11 +0000] [10] [INFO] Shutting down: Master
2020-10-04 17:51:11 default[20201004t144116]  [2020-10-04 17:51:11 +0000] [10] [INFO] Reason: Worker failed to boot.
2020-10-04 17:51:11 default[20201004t144116]  "GET /favicon.ico HTTP/1.1" 502
2020-10-04 17:51:13 default[20201004t144116]  [2020-10-04 17:51:13 +0000] [10] [INFO] Starting gunicorn 20.0.4
2020-10-04 17:51:13 default[20201004t144116]  [2020-10-04 17:51:13 +0000] [10] [INFO] Listening at: http://0.0.0.0:8081 (10)
2020-10-04 17:51:13 default[20201004t144116]  [2020-10-04 17:51:13 +0000] [10] [INFO] Using worker: threads
2020-10-04 17:51:13 default[20201004t144116]  [2020-10-04 17:51:13 +0000] [21] [INFO] Booting worker with pid: 21
2020-10-04 17:51:13 default[20201004t144116]  [2020-10-04 17:51:13 +0000] [24] [INFO] Booting worker with pid: 24
2020-10-04 17:51:14 default[20201004t144116]  /layers/google.python.pip/pip/flask_sqlalchemy/__init__.py:833: FSADeprecationWarning: SQLALCHEMY_TRACK_MODIFICATIONS adds significant overhead and will be disabled by default in the future.  Set it to True or False to suppress this warning.
2020-10-04 17:51:14 default[20201004t144116]    warnings.warn(FSADeprecationWarning(
2020-10-04 17:51:14 default[20201004t144116]  /layers/google.python.pip/pip/flask_sqlalchemy/__init__.py:833: FSADeprecationWarning: SQLALCHEMY_TRACK_MODIFICATIONS adds significant overhead and will be disabled by default in the future.  Set it to True or False to suppress this warning.
2020-10-04 17:51:14 default[20201004t144116]    warnings.warn(FSADeprecationWarning(
2020-10-04 17:51:14 default[20201004t144116]   * Serving Flask app "app" (lazy loading)
2020-10-04 17:51:14 default[20201004t144116]   * Environment: production
2020-10-04 17:51:14 default[20201004t144116]     WARNING: This is a development server. Do not use it in a production deployment.
2020-10-04 17:51:14 default[20201004t144116]     Use a production WSGI server instead.
2020-10-04 17:51:14 default[20201004t144116]   * Debug mode: on
2020-10-04 17:51:14 default[20201004t144116]   * Serving Flask app "app" (lazy loading)
2020-10-04 17:51:14 default[20201004t144116]   * Environment: production
2020-10-04 17:51:14 default[20201004t144116]     WARNING: This is a development server. Do not use it in a production deployment.
2020-10-04 17:51:14 default[20201004t144116]     Use a production WSGI server instead.
2020-10-04 17:51:14 default[20201004t144116]   * Debug mode: on
2020-10-04 17:51:15 default[20201004t144116]  [2020-10-04 17:51:15 +0000] [21] [ERROR] Exception in worker process
2020-10-04 17:51:15 default[20201004t144116]  Traceback (most recent call last):    File "/layers/google.python.webserver/gunicorn/gunicorn/arbiter.py", line 583, in spawn_worker      worker.init_process()    File "/layers/google.python.webserver/gunicorn/gunicorn/workers/gthread.py", line 92, in init_process      super().init_process()    File "/layers/google.python.webserver/gunicorn/gunicorn/workers/base.py", line 119, in init_process      self.load_wsgi()    File "/layers/google.python.webserver/gunicorn/gunicorn/workers/base.py", line 144, in load_wsgi      self.wsgi = self.app.wsgi()    File "/layers/google.python.webserver/gunicorn/gunicorn/app/base.py", line 67, in wsgi      self.callable = self.load()    File "/layers/google.python.webserver/gunicorn/gunicorn/app/wsgiapp.py", line 49, in load      return self.load_wsgiapp()    File "/layers/google.python.webserver/gunicorn/gunicorn/app/wsgiapp.py", line 39, in load_wsgiapp      return util.import_app(self.app_uri)    File "/layers/google.python.webserver/gunicorn/gunicorn/util.py", line 358, in import_app      mod = importlib.import_module(module)    File "/opt/python3.8/lib/python3.8/importlib/__init__.py", line 127, in import_module      return _bootstrap._gcd_import(name[level:], package, level)    File "<frozen importlib._bootstrap>", line 1014, in _gcd_import    File "<frozen importlib._bootstrap>", line 991, in _find_and_load    File "<frozen importlib._bootstrap>", line 975, in _find_and_load_unlocked    File "<frozen importlib._bootstrap>", line 671, in _load_unlocked    File "<frozen importlib._bootstrap_external>", line 783, in exec_module    File "<frozen importlib._bootstrap>", line 219, in _call_with_frames_removed    File "/srv/main.py", line 7, in <module>      app.run(debug=True, host="0.0.0.0", port=port)    File "/layers/google.python.pip/pip/flask/app.py", line 990, in run      run_simple(host, port, self, **options)    File "/layers/google.python.pip/pip/werkzeug/serving.py", line 1030, in run_simple      s.bind(server_address)  OSError: [Errno 98] Address already in use
2020-10-04 17:51:15 default[20201004t144116]  [2020-10-04 17:51:15 +0000] [21] [INFO] Worker exiting (pid: 21)
2020-10-04 17:51:15 default[20201004t144116]  [2020-10-04 17:51:15 +0000] [24] [ERROR] Exception in worker process
2020-10-04 17:51:15 default[20201004t144116]  Traceback (most recent call last):    File "/layers/google.python.webserver/gunicorn/gunicorn/arbiter.py", line 583, in spawn_worker      worker.init_process()    File "/layers/google.python.webserver/gunicorn/gunicorn/workers/gthread.py", line 92, in init_process      super().init_process()    File "/layers/google.python.webserver/gunicorn/gunicorn/workers/base.py", line 119, in init_process      self.load_wsgi()    File "/layers/google.python.webserver/gunicorn/gunicorn/workers/base.py", line 144, in load_wsgi      self.wsgi = self.app.wsgi()    File "/layers/google.python.webserver/gunicorn/gunicorn/app/base.py", line 67, in wsgi      self.callable = self.load()    File "/layers/google.python.webserver/gunicorn/gunicorn/app/wsgiapp.py", line 49, in load      return self.load_wsgiapp()    File "/layers/google.python.webserver/gunicorn/gunicorn/app/wsgiapp.py", line 39, in load_wsgiapp      return util.import_app(self.app_uri)    File "/layers/google.python.webserver/gunicorn/gunicorn/util.py", line 358, in import_app      mod = importlib.import_module(module)    File "/opt/python3.8/lib/python3.8/importlib/__init__.py", line 127, in import_module      return _bootstrap._gcd_import(name[level:], package, level)    File "<frozen importlib._bootstrap>", line 1014, in _gcd_import    File "<frozen importlib._bootstrap>", line 991, in _find_and_load    File "<frozen importlib._bootstrap>", line 975, in _find_and_load_unlocked    File "<frozen importlib._bootstrap>", line 671, in _load_unlocked    File "<frozen importlib._bootstrap_external>", line 783, in exec_module    File "<frozen importlib._bootstrap>", line 219, in _call_with_frames_removed    File "/srv/main.py", line 7, in <module>      app.run(debug=True, host="0.0.0.0", port=port)    File "/layers/google.python.pip/pip/flask/app.py", line 990, in run      run_simple(host, port, self, **options)    File "/layers/google.python.pip/pip/werkzeug/serving.py", line 1030, in run_simple      s.bind(server_address)  OSError: [Errno 98] Address already in use
2020-10-04 17:51:15 default[20201004t144116]  [2020-10-04 17:51:15 +0000] [24] [INFO] Worker exiting (pid: 24)
2020-10-04 17:51:15 default[20201004t144116]  [2020-10-04 17:51:15 +0000] [10] [INFO] Shutting down: Master
2020-10-04 17:51:15 default[20201004t144116]  [2020-10-04 17:51:15 +0000] [10] [INFO] Reason: Worker failed to boot.
2020-10-04 17:52:38 default[20201004t144116]  "GET / HTTP/1.1" 502
2020-10-04 17:52:39 default[20201004t144116]  [2020-10-04 17:52:39 +0000] [10] [INFO] Starting gunicorn 20.0.4
2020-10-04 17:52:39 default[20201004t144116]  [2020-10-04 17:52:39 +0000] [10] [INFO] Listening at: http://0.0.0.0:8081 (10)
2020-10-04 17:52:39 default[20201004t144116]  [2020-10-04 17:52:39 +0000] [10] [INFO] Using worker: threads
2020-10-04 17:52:39 default[20201004t144116]  [2020-10-04 17:52:39 +0000] [21] [INFO] Booting worker with pid: 21
2020-10-04 17:52:39 default[20201004t144116]  [2020-10-04 17:52:39 +0000] [25] [INFO] Booting worker with pid: 25
2020-10-04 17:52:41 default[20201004t144116]  /layers/google.python.pip/pip/flask_sqlalchemy/__init__.py:833: FSADeprecationWarning: SQLALCHEMY_TRACK_MODIFICATIONS adds significant overhead and will be disabled by default in the future.  Set it to True or False to suppress this warning.
2020-10-04 17:52:41 default[20201004t144116]    warnings.warn(FSADeprecationWarning(
2020-10-04 17:52:41 default[20201004t144116]  /layers/google.python.pip/pip/flask_sqlalchemy/__init__.py:833: FSADeprecationWarning: SQLALCHEMY_TRACK_MODIFICATIONS adds significant overhead and will be disabled by default in the future.  Set it to True or False to suppress this warning.
2020-10-04 17:52:41 default[20201004t144116]    warnings.warn(FSADeprecationWarning(
2020-10-04 17:52:41 default[20201004t144116]   * Serving Flask app "app" (lazy loading)
2020-10-04 17:52:41 default[20201004t144116]   * Environment: production
2020-10-04 17:52:41 default[20201004t144116]     WARNING: This is a development server. Do not use it in a production deployment.
2020-10-04 17:52:41 default[20201004t144116]     Use a production WSGI server instead.
2020-10-04 17:52:41 default[20201004t144116]   * Debug mode: on
2020-10-04 17:52:41 default[20201004t144116]   * Serving Flask app "app" (lazy loading)
2020-10-04 17:52:41 default[20201004t144116]   * Environment: production
2020-10-04 17:52:41 default[20201004t144116]     WARNING: This is a development server. Do not use it in a production deployment.
2020-10-04 17:52:41 default[20201004t144116]     Use a production WSGI server instead.
2020-10-04 17:52:41 default[20201004t144116]   * Debug mode: on
2020-10-04 17:52:41 default[20201004t144116]  [2020-10-04 17:52:41 +0000] [25] [ERROR] Exception in worker process
2020-10-04 17:52:41 default[20201004t144116]  Traceback (most recent call last):    File "/layers/google.python.webserver/gunicorn/gunicorn/arbiter.py", line 583, in spawn_worker      worker.init_process()    File "/layers/google.python.webserver/gunicorn/gunicorn/workers/gthread.py", line 92, in init_process      super().init_process()    File "/layers/google.python.webserver/gunicorn/gunicorn/workers/base.py", line 119, in init_process      self.load_wsgi()    File "/layers/google.python.webserver/gunicorn/gunicorn/workers/base.py", line 144, in load_wsgi      self.wsgi = self.app.wsgi()    File "/layers/google.python.webserver/gunicorn/gunicorn/app/base.py", line 67, in wsgi      self.callable = self.load()    File "/layers/google.python.webserver/gunicorn/gunicorn/app/wsgiapp.py", line 49, in load      return self.load_wsgiapp()    File "/layers/google.python.webserver/gunicorn/gunicorn/app/wsgiapp.py", line 39, in load_wsgiapp      return util.import_app(self.app_uri)    File "/layers/google.python.webserver/gunicorn/gunicorn/util.py", line 358, in import_app      mod = importlib.import_module(module)    File "/opt/python3.8/lib/python3.8/importlib/__init__.py", line 127, in import_module      return _bootstrap._gcd_import(name[level:], package, level)    File "<frozen importlib._bootstrap>", line 1014, in _gcd_import    File "<frozen importlib._bootstrap>", line 991, in _find_and_load    File "<frozen importlib._bootstrap>", line 975, in _find_and_load_unlocked    File "<frozen importlib._bootstrap>", line 671, in _load_unlocked    File "<frozen importlib._bootstrap_external>", line 783, in exec_module    File "<frozen importlib._bootstrap>", line 219, in _call_with_frames_removed    File "/srv/main.py", line 7, in <module>      app.run(debug=True, host="0.0.0.0", port=port)    File "/layers/google.python.pip/pip/flask/app.py", line 990, in run      run_simple(host, port, self, **options)    File "/layers/google.python.pip/pip/werkzeug/serving.py", line 1030, in run_simple      s.bind(server_address)  OSError: [Errno 98] Address already in use
2020-10-04 17:52:41 default[20201004t144116]  [2020-10-04 17:52:41 +0000] [21] [ERROR] Exception in worker process
2020-10-04 17:52:41 default[20201004t144116]  Traceback (most recent call last):    File "/layers/google.python.webserver/gunicorn/gunicorn/arbiter.py", line 583, in spawn_worker      worker.init_process()    File "/layers/google.python.webserver/gunicorn/gunicorn/workers/gthread.py", line 92, in init_process      super().init_process()    File "/layers/google.python.webserver/gunicorn/gunicorn/workers/base.py", line 119, in init_process      self.load_wsgi()    File "/layers/google.python.webserver/gunicorn/gunicorn/workers/base.py", line 144, in load_wsgi      self.wsgi = self.app.wsgi()    File "/layers/google.python.webserver/gunicorn/gunicorn/app/base.py", line 67, in wsgi      self.callable = self.load()    File "/layers/google.python.webserver/gunicorn/gunicorn/app/wsgiapp.py", line 49, in load      return self.load_wsgiapp()    File "/layers/google.python.webserver/gunicorn/gunicorn/app/wsgiapp.py", line 39, in load_wsgiapp      return util.import_app(self.app_uri)    File "/layers/google.python.webserver/gunicorn/gunicorn/util.py", line 358, in import_app      mod = importlib.import_module(module)    File "/opt/python3.8/lib/python3.8/importlib/__init__.py", line 127, in import_module      return _bootstrap._gcd_import(name[level:], package, level)    File "<frozen importlib._bootstrap>", line 1014, in _gcd_import    File "<frozen importlib._bootstrap>", line 991, in _find_and_load    File "<frozen importlib._bootstrap>", line 975, in _find_and_load_unlocked    File "<frozen importlib._bootstrap>", line 671, in _load_unlocked    File "<frozen importlib._bootstrap_external>", line 783, in exec_module    File "<frozen importlib._bootstrap>", line 219, in _call_with_frames_removed    File "/srv/main.py", line 7, in <module>      app.run(debug=True, host="0.0.0.0", port=port)    File "/layers/google.python.pip/pip/flask/app.py", line 990, in run      run_simple(host, port, self, **options)    File "/layers/google.python.pip/pip/werkzeug/serving.py", line 1030, in run_simple      s.bind(server_address)  OSError: [Errno 98] Address already in use
2020-10-04 17:52:41 default[20201004t144116]  [2020-10-04 17:52:41 +0000] [25] [INFO] Worker exiting (pid: 25)
2020-10-04 17:52:41 default[20201004t144116]  [2020-10-04 17:52:41 +0000] [21] [INFO] Worker exiting (pid: 21)
2020-10-04 17:52:41 default[20201004t144116]  Traceback (most recent call last):    File "/layers/google.python.webserver/gunicorn/gunicorn/arbiter.py", line 209, in run      self.sleep()    File "/layers/google.python.webserver/gunicorn/gunicorn/arbiter.py", line 357, in sleep      ready = select.select([self.PIPE[0]], [], [], 1.0)    File "/layers/google.python.webserver/gunicorn/gunicorn/arbiter.py", line 242, in handle_chld      self.reap_workers()    File "/layers/google.python.webserver/gunicorn/gunicorn/arbiter.py", line 525, in reap_workers      raise HaltServer(reason, self.WORKER_BOOT_ERROR)  gunicorn.errors.HaltServer: <HaltServer 'Worker failed to boot.' 3>
2020-10-04 17:52:41 default[20201004t144116]
2020-10-04 17:52:41 default[20201004t144116]  During handling of the above exception, another exception occurred:
2020-10-04 17:52:41 default[20201004t144116]
2020-10-04 17:52:41 default[20201004t144116]  Traceback (most recent call last):    File "/layers/google.python.webserver/gunicorn/gunicorn/arbiter.py", line 636, in kill_worker      os.kill(pid, sig)  ProcessLookupError: [Errno 3] No such process
2020-10-04 17:52:41 default[20201004t144116]
2020-10-04 17:52:41 default[20201004t144116]  During handling of the above exception, another exception occurred:
2020-10-04 17:52:41 default[20201004t144116]
2020-10-04 17:52:41 default[20201004t144116]  Traceback (most recent call last):    File "/layers/google.python.webserver/gunicorn/bin/gunicorn", line 8, in <module>      sys.exit(run())    File "/layers/google.python.webserver/gunicorn/gunicorn/app/wsgiapp.py", line 58, in run      WSGIApplication("%(prog)s [OPTIONS] [APP_MODULE]").run()    File "/layers/google.python.webserver/gunicorn/gunicorn/app/base.py", line 228, in run      super().run()    File "/layers/google.python.webserver/gunicorn/gunicorn/app/base.py", line 72, in run      Arbiter(self).run()    File "/layers/google.python.webserver/gunicorn/gunicorn/arbiter.py", line 229, in run      self.halt(reason=inst.reason, exit_status=inst.exit_status)    File "/layers/google.python.webserver/gunicorn/gunicorn/arbiter.py", line 342, in halt      self.stop()    File "/layers/google.python.webserver/gunicorn/gunicorn/arbiter.py", line 390, in stop      self.kill_workers(sig)    File "/layers/google.python.webserver/gunicorn/gunicorn/arbiter.py", line 626, in kill_workers      self.kill_worker(pid, sig)    File "/layers/google.python.webserver/gunicorn/gunicorn/arbiter.py", line 636, in kill_worker      os.kill(pid, sig)    File "/layers/google.python.webserver/gunicorn/gunicorn/arbiter.py", line 242, in handle_chld      self.reap_workers()    File "/layers/google.python.webserver/gunicorn/gunicorn/arbiter.py", line 525, in reap_workers      raise HaltServer(reason, self.WORKER_BOOT_ERROR)  gunicorn.errors.HaltServer: <HaltServer 'Worker failed to boot.' 3>
2020-10-04 17:52:42 default[20201004t144116]  "GET /favicon.ico HTTP/1.1" 502
2020-10-04 17:52:43 default[20201004t144116]  [2020-10-04 17:52:43 +0000] [10] [INFO] Starting gunicorn 20.0.4
2020-10-04 17:52:43 default[20201004t144116]  [2020-10-04 17:52:43 +0000] [10] [INFO] Listening at: http://0.0.0.0:8081 (10)
2020-10-04 17:52:43 default[20201004t144116]  [2020-10-04 17:52:43 +0000] [10] [INFO] Using worker: threads
2020-10-04 17:52:43 default[20201004t144116]  [2020-10-04 17:52:43 +0000] [21] [INFO] Booting worker with pid: 21
2020-10-04 17:52:43 default[20201004t144116]  [2020-10-04 17:52:43 +0000] [24] [INFO] Booting worker with pid: 24
2020-10-04 17:52:44 default[20201004t144116]  /layers/google.python.pip/pip/flask_sqlalchemy/__init__.py:833: FSADeprecationWarning: SQLALCHEMY_TRACK_MODIFICATIONS adds significant overhead and will be disabled by default in the future.  Set it to True or False to suppress this warning.
2020-10-04 17:52:44 default[20201004t144116]    warnings.warn(FSADeprecationWarning(
2020-10-04 17:52:44 default[20201004t144116]  /layers/google.python.pip/pip/flask_sqlalchemy/__init__.py:833: FSADeprecationWarning: SQLALCHEMY_TRACK_MODIFICATIONS adds significant overhead and will be disabled by default in the future.  Set it to True or False to suppress this warning.
2020-10-04 17:52:44 default[20201004t144116]    warnings.warn(FSADeprecationWarning(
2020-10-04 17:52:44 default[20201004t144116]   * Serving Flask app "app" (lazy loading)
2020-10-04 17:52:44 default[20201004t144116]   * Environment: production
2020-10-04 17:52:44 default[20201004t144116]     WARNING: This is a development server. Do not use it in a production deployment.
2020-10-04 17:52:44 default[20201004t144116]     Use a production WSGI server instead.
2020-10-04 17:52:44 default[20201004t144116]   * Debug mode: on
2020-10-04 17:52:44 default[20201004t144116]   * Serving Flask app "app" (lazy loading)
2020-10-04 17:52:44 default[20201004t144116]   * Environment: production
2020-10-04 17:52:44 default[20201004t144116]     WARNING: This is a development server. Do not use it in a production deployment.
2020-10-04 17:52:44 default[20201004t144116]     Use a production WSGI server instead.
2020-10-04 17:52:44 default[20201004t144116]   * Debug mode: on
2020-10-04 17:52:44 default[20201004t144116]  [2020-10-04 17:52:44 +0000] [21] [ERROR] Exception in worker process
2020-10-04 17:52:44 default[20201004t144116]  Traceback (most recent call last):    File "/layers/google.python.webserver/gunicorn/gunicorn/arbiter.py", line 583, in spawn_worker      worker.init_process()    File "/layers/google.python.webserver/gunicorn/gunicorn/workers/gthread.py", line 92, in init_process      super().init_process()    File "/layers/google.python.webserver/gunicorn/gunicorn/workers/base.py", line 119, in init_process      self.load_wsgi()    File "/layers/google.python.webserver/gunicorn/gunicorn/workers/base.py", line 144, in load_wsgi      self.wsgi = self.app.wsgi()    File "/layers/google.python.webserver/gunicorn/gunicorn/app/base.py", line 67, in wsgi      self.callable = self.load()    File "/layers/google.python.webserver/gunicorn/gunicorn/app/wsgiapp.py", line 49, in load      return self.load_wsgiapp()    File "/layers/google.python.webserver/gunicorn/gunicorn/app/wsgiapp.py", line 39, in load_wsgiapp      return util.import_app(self.app_uri)    File "/layers/google.python.webserver/gunicorn/gunicorn/util.py", line 358, in import_app      mod = importlib.import_module(module)    File "/opt/python3.8/lib/python3.8/importlib/__init__.py", line 127, in import_module      return _bootstrap._gcd_import(name[level:], package, level)    File "<frozen importlib._bootstrap>", line 1014, in _gcd_import    File "<frozen importlib._bootstrap>", line 991, in _find_and_load    File "<frozen importlib._bootstrap>", line 975, in _find_and_load_unlocked    File "<frozen importlib._bootstrap>", line 671, in _load_unlocked    File "<frozen importlib._bootstrap_external>", line 783, in exec_module    File "<frozen importlib._bootstrap>", line 219, in _call_with_frames_removed    File "/srv/main.py", line 7, in <module>      app.run(debug=True, host="0.0.0.0", port=port)    File "/layers/google.python.pip/pip/flask/app.py", line 990, in run      run_simple(host, port, self, **options)    File "/layers/google.python.pip/pip/werkzeug/serving.py", line 1030, in run_simple      s.bind(server_address)  OSError: [Errno 98] Address already in use
2020-10-04 17:52:44 default[20201004t144116]  [2020-10-04 17:52:44 +0000] [21] [INFO] Worker exiting (pid: 21)
2020-10-04 17:52:44 default[20201004t144116]  [2020-10-04 17:52:44 +0000] [24] [ERROR] Exception in worker process
2020-10-04 17:52:44 default[20201004t144116]  Traceback (most recent call last):    File "/layers/google.python.webserver/gunicorn/gunicorn/arbiter.py", line 583, in spawn_worker      worker.init_process()    File "/layers/google.python.webserver/gunicorn/gunicorn/workers/gthread.py", line 92, in init_process      super().init_process()    File "/layers/google.python.webserver/gunicorn/gunicorn/workers/base.py", line 119, in init_process      self.load_wsgi()    File "/layers/google.python.webserver/gunicorn/gunicorn/workers/base.py", line 144, in load_wsgi      self.wsgi = self.app.wsgi()    File "/layers/google.python.webserver/gunicorn/gunicorn/app/base.py", line 67, in wsgi      self.callable = self.load()    File "/layers/google.python.webserver/gunicorn/gunicorn/app/wsgiapp.py", line 49, in load      return self.load_wsgiapp()    File "/layers/google.python.webserver/gunicorn/gunicorn/app/wsgiapp.py", line 39, in load_wsgiapp      return util.import_app(self.app_uri)    File "/layers/google.python.webserver/gunicorn/gunicorn/util.py", line 358, in import_app      mod = importlib.import_module(module)    File "/opt/python3.8/lib/python3.8/importlib/__init__.py", line 127, in import_module      return _bootstrap._gcd_import(name[level:], package, level)    File "<frozen importlib._bootstrap>", line 1014, in _gcd_import    File "<frozen importlib._bootstrap>", line 991, in _find_and_load    File "<frozen importlib._bootstrap>", line 975, in _find_and_load_unlocked    File "<frozen importlib._bootstrap>", line 671, in _load_unlocked    File "<frozen importlib._bootstrap_external>", line 783, in exec_module    File "<frozen importlib._bootstrap>", line 219, in _call_with_frames_removed    File "/srv/main.py", line 7, in <module>      app.run(debug=True, host="0.0.0.0", port=port)    File "/layers/google.python.pip/pip/flask/app.py", line 990, in run      run_simple(host, port, self, **options)    File "/layers/google.python.pip/pip/werkzeug/serving.py", line 1030, in run_simple      s.bind(server_address)  OSError: [Errno 98] Address already in use
